Workbook
Name datapivot: INDIRECT(CONCATENATE("Data!","$A$1:$AH$",COUNTA([1]Data!$A:$A)))
Name Intervalle: Liste!$N$2:$N$33
Name Parcours: Liste!$G$2:$G$3
Name Rame: Liste!$B$2:$B$13

Sheet Data
A1: N° ordre | B1: 7 derniers jours? | C1: Date | D1: Heure | E1: N° Train | F1: Rame | G1: Motrice / Cab | H1: MRM | I1: IMEI | J1: Sens | K1: Km | L1: Intervalle | M1: Niveau ETCS | N1: Evénement | O1: Cause_racine | P1: Analyse SMMRGV | Q1: Sous Système mis en cause | R1: Action | S1: Execution HO | T1: RxQual | U1: RxLev | V1: Voisinage (10sec) | W1: Com DTE-DCE | X1: Ecart | Y1: Retransmission trames HDLC/T.70 | Z1: Alarmes BTS | AA1: Traité par | AB1: CIRE | AC1: CIERS | AD1: Acquittement AUC | AE1: BUG RBC | AF1: Liens PAI | AG1: Pilote | AH1: Échéance
A2: 1 | B2: =AND(C2>=TODAY()-7, C2<=TODAY()-1) -> FALSE | C2: 45297 | D2: 0.38918981 | E2: 2013 | F2: 1208 | G2: M1 | H2: 1037 | I2: 35214500045488 | J2: Tanger/Casa | K2: 68.956 | L2: =VLOOKUP(K2,Liste!$L$2:$O$34,4,1) -> GSMR_12/13 | M2: N2 | N2: Ralentissement du train | O2: H.O non finalisé entre 212 et 213,bonne qualité / niveau de signal Requête de déconnexion a été envoyé par le RBC | Q2: BORD | S2: H.O non finalisé entre 212 et 213 | T2: dl Rxqual=3 | U2: dl rx level= -63 dbm | V2: NOK | W2: NOK | X2: moyenne | Y2: retransmission des trames HDLC*5
A3: 2 | B3: =AND(C3>=TODAY()-7, C3<=TODAY()-1) -> FALSE | C3: 45301 | D3: 0.43631944 | E3: 2017 | F3: 1211 | G3: M1 | H3: 1029 | I3: 35214500045449 | J3: Tanger/Casa | K3: 108.206 | L3: =VLOOKUP(K3,Liste!$L$2:$O$34,4,1) -> GSMR_19/20 | M3: N2 | N3: Ralentissement du train | O3: H.O non finalisé entre 219 et 220,bonne qualité / niveau de signal Requête de déconnexion a été envoyé par le RBC | Q3: GSMR | R3: dans l'attente des mesures radio | S3: recule non reussi entre 219 et 220 | T3: dl Rxqual=3 | U3: dl rx level= -78 dbm | V3: NOK | W3: OK | X3: Mauvais | Y3: retransmission des trames HDLC*5
A4: 3 | B4: =AND(C4>=TODAY()-7, C4<=TODAY()-1) -> FALSE | C4: 45301 | D4: 0.33729167 | E4: 2009 | F4: 1205 | G4: M1 | H4: 7217 | I4: 35214500044557 | J4: Tanger/Casa | K4: 6.13 | L4: =VLOOKUP(K4,Liste!$L$2:$O$34,4,1) -> GSMR_02/03 | M4: N2 | N4: Ralentissement du train | O4: recule non reussi 202 et 201,Mauvaise qualité de signal Requête de déconnexion a été envoyé par le RBC | Q4: BORD/GSMR | S4: recule non reussi entre 202 et 201 | T4: dl Rxqual=7 | U4: dl rx level= -53 dbm | V4: NOK | W4: OK | X4: Mauvais | Y4: retransmission des trames HDLC*5
A5: 4 | B5: =AND(C5>=TODAY()-7, C5<=TODAY()-1) -> FALSE | C5: 45302 | D5: 0.67072917 | E5: 2041 | F5: 1207 | G5: M1 | H5: 1046 | I5: 35214500038730 | J5: Tanger/Casa | K5: 6.13 | L5: =VLOOKUP(K5,Liste!$L$2:$O$34,4,1) -> GSMR_02/03 | M5: N2 | N5: Arrêt du train | O5: H.O non finalisé entre 202 et 203,Mauvaise qualité de signal Requête de déconnexion a été envoyé par le RBC | Q5: GSMR | R5: Le 14/01 Changement de cable coaxial de la rame 1207 M1 | S5: H.O non finalisé entre 202 et 203 | T5: dl Rxqual=7 | U5: dl rx level= -53 dbm | V5: NOK | W5: OK | X5: moyenne | Y5: retransmission des trames HDLC*5
A6: 5 | B6: =AND(C6>=TODAY()-7, C6<=TODAY()-1) -> FALSE | C6: 45304 | D6: 0.60820602 | E6: 2033 | F6: 1209 | G6: M1 | H6: 7208 | I6: 35214500004427 | J6: Tanger/Casa | K6: 147.876 | L6: =VLOOKUP(K6,Liste!$L$2:$O$34,4,1) -> GSMR_25/26 | M6: N2 | N6: Ralentissement du train | O6: enchainement 325->226->228->227 ; mauvaise qualité de signal , requête déconnexion envoyé par le RBC | Q6: BORD/GSMR | R6: le 09/01 verification de VSWR de l'antenne de la rame 1209 M1 | S6: 325->226->228->227 | T6: dl Rxqual=7 | U6: dl rx level= -97 dbm | V6: NOK | X6: moyenne | Y6: retransmission des trames HDLC*3
A7: 6 | B7: =AND(C7>=TODAY()-7, C7<=TODAY()-1) -> FALSE | C7: 45307 | D7: 0.52515046 | E7: 2025 | F7: 1207 | G7: M1 | H7: 1046 | I7: 35214500038730 | J7: Tanger/Casa | K7: 147.876 | L7: =VLOOKUP(K7,Liste!$L$2:$O$34,4,1) -> GSMR_25/26 | M7: N2 | N7: Ralentissement du train | O7: recule de la cellule 327 vers la cellule 325 , bonne qualité/niveau de signal , requête déconnexion envoyé par le RBC | Q7: BORD/GSMR | S7: recule 327 vers 325 | T7: dl Rxqual=0 | U7: dl rx level= -79 dbm | V7: NOK | W7: OK | X7: moyenne | Y7: retransmission des trames HDLC*5
A8: 7 | B8: =AND(C8>=TODAY()-7, C8<=TODAY()-1) -> FALSE | C8: 45308 | D8: 0.71152778 | E8: 1037 | F8: 1203 | G8: M2 | H8: 1026 | I8: 35214500045083 | J8: Casa/Tanger | K8: 7.321 | L8: =VLOOKUP(K8,Liste!$L$2:$O$34,4,1) -> GSMR_02/03 | M8: N2 | N8: Arrêt du train | O8: H.O complet entre 303 et 202,Mauvaise qualité de signal Requête de déconnexion a été envoyé par le Bord | Q8: GSMR | S8: H.O Complet entre 303 et 202 | T8: dl Rxqual=7 | U8: dl rx level= -57 dbm | V8: OK | W8: OK | X8: moyenne | Y8: retransmission des trames HDLC*5
A9: 8 | B9: =AND(C9>=TODAY()-7, C9<=TODAY()-1) -> FALSE | C9: 45308 | D9: 0.44628472 | E9: 2017 | F9: 1212 | G9: M1 | H9: 1057 | I9: 35214500045187 | J9: Tanger/Casa | K9: 179.149 | L9: =VLOOKUP(K9,Liste!$L$2:$O$34,4,1) -> GSMR_30/31 | M9: N2 | N9: Ralentissement du train | O9: H.O non finalisé entre 230 et 231,bonne qualité / niveau de signal Requête de déconnexion a été envoyé par le RBC | Q9: BORD | S9: H.O non finalisé entre 230 et 231 | T9: dl Rxqual=2 | U9: dl rx level= -69 dbm | V9: OK | W9: OK | X9: moyenne | Y9: retransmission des trames HDLC*5
A10: 9 | B10: =AND(C10>=TODAY()-7, C10<=TODAY()-1) -> FALSE | C10: 45311 | D10: 0.68394676 | E10: 1037 | F10: 1206 | G10: M2 | H10: 1040 | J10: Casa/Tanger | K10: 202.125 | L10: =VLOOKUP(K10,Liste!$L$2:$O$34,4,1) -> GSMR_33/RAC | M10: N2 | N10: Ralentissement du train | O10: H.O complet entre 234 et 333,Mauvaise qualité de signal Requête de déconnexion a été envoyé par le RBC | Q10: GSMR | S10: H.O Complet entre 234 et 333 | T10: dl Rxqual=7 | U10: dl rx level= -65 dbm | V10: NOK | W10: OK | X10: moyenne | Y10: retransmission des trames HDLC*5
A11: 10 | B11: =AND(C11>=TODAY()-7, C11<=TODAY()-1) -> FALSE | C11: 45313 | D11: 0.86572917 | F11: 1202 | G11: M2 | H11: 1022 | I11: 35214500045326 | J11: Casa/Tanger | K11: 127.815 | L11: =VLOOKUP(K11,Liste!$L$2:$O$34,4,1) -> GSMR_22/23 | M11: N2 | N11: Ralentissement du train | O11: H.O non finalisé entre 223 et 222,Mauvaise qualité de signal Requête de déconnexion a été envoyé par le RBC | Q11: GSMR | S11: H.O non finalisé entre 223 et 222 | T11: dl Rxqual=7 | U11: dl rx level= -66 dbm | V11: OK | W11: OK | X11: mauvais | Y11: retransmission des trames HDLC*5
A12: 11 | B12: =AND(C12>=TODAY()-7, C12<=TODAY()-1) -> FALSE | C12: 45313 | D12: 0.71731481 | E12: 1037 | F12: 1203 | G12: M2 | H12: 1026 | I12: 35214500045083 | J12: Casa/Tanger | K12: 7.321 | L12: =VLOOKUP(K12,Liste!$L$2:$O$34,4,1) -> GSMR_02/03 | M12: N2 | N12: Arrêt du train | O12: H.O complet entre 303 et 202,Mauvaise qualité de signal Requête de déconnexion a été envoyé par le RBC | Q12: BORD/GSMR | S12: H.O Complet entre 303 et 202 | T12: dl Rxqual=7 | U12: dl rx level= -57 dbm | V12: OK | W12: OK | X12: moyenne | Y12: retransmission des trames HDLC*5
A13: 12 | B13: =AND(C13>=TODAY()-7, C13<=TODAY()-1) -> FALSE | C13: 45314 | D13: 0.76916667 | E13: 2049 | F13: 1209 | G13: M1 | H13: 7208 | I13: 35214500004427 | J13: Tanger/Casa | K13: 108.206 | L13: =VLOOKUP(K13,Liste!$L$2:$O$34,4,1) -> GSMR_19/20 | M13: N2 | N13: Ralentissement du train | O13: H.O complet entre 219 et 320,Mauvaise qualité de signal Requête de déconnexion a été envoyé par le Bord | Q13: BORD | S13: H.O Complet entre 219 et 320 | T13: dl Rxqual=7 | U13: dl rx level= -70 dbm | V13: OK | W13: OK | X13: moyenne | Y13: retransmission des trames HDLC*3
A14: 13 | B14: =AND(C14>=TODAY()-7, C14<=TODAY()-1) -> FALSE | C14: 45315 | D14: 0.7166088 | E14: 2045 | F14: 1208 | G14: M1 | H14: 1037 | I14: 35214500045488 | J14: Tanger/Casa | K14: 25.91 | L14: =VLOOKUP(K14,Liste!$L$2:$O$34,4,1) -> GSMR_05/06 | M14: N2 | N14: Ralentissement du train | O14: H.O non finalisé entre 205 et 206,Mauvaise qualité de signal Requête de déconnexion a été envoyé par le RBC | Q14: BORD | S14: H.O non finalisé entre 205 et 206 | T14: dl Rxqual=6 | U14: dl rx level= -87 dbm | V14: NOK | W14: OK | X14: moyenne | Y14: retransmission des trames HDLC*5
A15: 14 | B15: =AND(C15>=TODAY()-7, C15<=TODAY()-1) -> FALSE | C15: 45315 | D15: 0.93679398 | E15: 1061 | F15: 1212 | G15: M2 | H15: 1072 | I15: 35214500045424 | J15: Casa/Tanger | K15: 177.85 | L15: =VLOOKUP(K15,Liste!$L$2:$O$34,4,1) -> GSMR_30/31 | M15: N2 | N15: Ralentissement du train | O15: recule de la cellule 330vers la cellue 331,Mauvaise qualité de signal Requête de déconnexion a été envoyé par le RBC | Q15: BORD | S15: Recule de 330 vers 331 | T15: dl Rxqual=7 | U15: dl rx level= -68 dbm | V15: OK | W15: OK | X15: Bon | Y15: retransmission des trames HDLC*5
A16: 15 | B16: =AND(C16>=TODAY()-7, C16<=TODAY()-1) -> FALSE | C16: 45316 | D16: 0.77451389 | E16: 2049 | F16: 1204 | G16: M1 | H16: 1052 | I16: 35214500043740 | J16: Tanger/Casa | K16: 144.326 | L16: =VLOOKUP(K16,Liste!$L$2:$O$34,4,1) -> GSMR_25/26 | M16: N2 | N16: Arrêt du train | O16: H.O complet entre 224 et 225,Bonne qualité de signal Requête de déconnexion a été envoyé par le RBC | Q16: BORD | S16: H.O Complet entre 224 et 225 | T16: dl Rxqual=1 | U16: dl rx level= -64 dbm | V16: OK | W16: OK | X16: Mauvais | Y16: pas de retransmission des trames HDLC
A17: 16 | B17: =AND(C17>=TODAY()-7, C17<=TODAY()-1) -> FALSE | C17: 45317 | D17: 0.82337963 | F17: 1204 | G17: M2 | H17: 1030 | I17: 35214500045348 | J17: Casa/Tanger | K17: 96.317 | L17: =VLOOKUP(K17,Liste!$L$2:$O$34,4,1) -> GSMR_17/18 | M17: N2 | N17: Ralentissement du train | O17: H.O complet entre 319 et 318,Bonne qualité /niveau de signal Requête de déconnexion a été envoyé a travers la BTS | Q17: RBC | R17: En attente de verification des traces RBC | S17: H.O Complet entre 319 et318 | T17: dl Rxqual=0 | U17: dl rx level= -56 dbm | V17: OK | W17: NOK | X17: moyenne | Y17: retransmission des trames HDLC*5
A18: 17 | B18: =AND(C18>=TODAY()-7, C18<=TODAY()-1) -> FALSE | C18: 45318 | D18: 0.7777662 | E18: 1045 | F18: 1207 | G18: M2 | H18: 1007 | J18: Casa/Tanger | K18: 127.815 | L18: =VLOOKUP(K18,Liste!$L$2:$O$34,4,1) -> GSMR_22/23 | M18: N2 | N18: Ralentissement du train | O18: deux tentative de H.O nn reussi entre 323 et 322 ,mauvaise qualité de signal , requête déconnexion envoyé par le RBC | Q18: GSMR | R18: Permutation des cartes radio active / stand by au niveau de la cellule 22 le 05/02 | S18: H.O non finalisé entre 323 et 22 | T18: dl Rxqual=6 | U18: dl rx level= -77 dbm | V18: OK | W18: OK | X18: Mauvais | Y18: retransmission des trames HDLC*5
A19: 18 | B19: =AND(C19>=TODAY()-7, C19<=TODAY()-1) -> FALSE | C19: 45318 | D19: 0.81199074 | E19: 1049 | F19: 1212 | G19: M2 | H19: 1020 | I19: 35214500045494 | J19: Casa/Tanger | K19: 177.85 | L19: =VLOOKUP(K19,Liste!$L$2:$O$34,4,1) -> GSMR_30/31 | M19: N2 | N19: Ralentissement du train | O19: ping pong / recule non reussi entre 331 eeet 232 ,Mauvaise qualité de signal Requête de déconnexion a été envoyé par le Bord | Q19: BORD | R19: Attente reponse ingenieurie SMM-RGV | S19: Ping pong entre 330 et 331 | T19: dl Rxqual=5 | U19: dl rx level= -63 dbm | V19: OK | W19: OK | X19: Bon | Y19: retransmission des trames HDLC*5
A20: 19 | B20: =AND(C20>=TODAY()-7, C20<=TODAY()-1) -> FALSE | C20: 45318 | D20: 0.40195602 | E20: 2013 | F20: 1212 | G20: M1 | H20: 1056 | I20: 35214500045217 | J20: Tanger/Casa | K20: 162.895 | L20: =VLOOKUP(K20,Liste!$L$2:$O$34,4,1) -> GSMR_27/28 | M20: N2 | N20: Ralentissement du train | O20: H.O complet entre 327 et 328,Bonne qualité /niveau de signal Requête de déconnexion a été envoyé a travers la BTS | Q20: Signalisation | S20: H.O Complet entre 327et328 | T20: dl Rxqual=0 | U20: dl rx level= -48 dbm | V20: OK | W20: NOK | X20: Mauvais | Y20: retransmission des trames HDLC*5
A21: 20 | B21: =AND(C21>=TODAY()-7, C21<=TODAY()-1) -> FALSE | C21: 45318 | D21: 0.40196759 | F21: 1211 | G21: M2 | H21: 3063 | I21: 35214500046055 | J21: Casa/Tanger | K21: 130.484 | L21: =VLOOKUP(K21,Liste!$L$2:$O$34,4,1) -> GSMR_23/24 | M21: N2 | N21: Ralentissement du train | O21: H.O complet entre 324 et 323,Bonne qualité /niveau de signal Requête de déconnexion a été envoyé a travers la BTS | Q21: Signalisation | S21: H.O Complet entre 324 et323 | T21: dl Rxqual=0 | U21: dl rx level= -48 dbm | V21: OK | W21: NOK | X21: Mauvais | Y21: retransmission des trames HDLC*5
A22: 21 | B22: =AND(C22>=TODAY()-7, C22<=TODAY()-1) -> FALSE | C22: 45319 | D22: 0.3169213 | E22: 10075 | F22: 1212 | G22: M2 | H22: 1020 | I22: 35214500045494 | J22: Casa/Tanger | K22: 79.282 | L22: =VLOOKUP(K22,Liste!$L$2:$O$34,4,1) -> GSMR_14/15 | M22: N2 | N22: Ralentissement du train | O22: H.O complet entre 315 et 314,Bonne qualité /niveau de signal Requête de déconnexion a été envoyé par RBC | Q22: BORD | R22: Attente reponse ingenieurie SMM-RGV | S22: H.O Complet entre 315 et314 | T22: dl Rxqual=0 | U22: dl rx level= -59 dbm | V22: OK | W22: OK | X22: Mauvais | Y22: pas de retransmission des trames HDLC
A23: 22 | B23: =AND(C23>=TODAY()-7, C23<=TODAY()-1) -> FALSE | C23: 45320 | D23: 0.4624537 | E23: 1013 | F23: 1211 | G23: M2 | H23: 3062 | J23: Casa/Tanger | K23: 7.321 | L23: =VLOOKUP(K23,Liste!$L$2:$O$34,4,1) -> GSMR_02/03 | M23: N2 | N23: Ralentissement du train | O23: H.O complet entre 303 et 202,Bonne qualité /niveau de signal Requête de déconnexion a été envoyé par RBC | Q23: Non specifie | R23: Programmer une reunion afin d'analyser les traces | S23: H.O Complet entre 303 et202 | T23: dl Rxqual=0 | U23: dl rx level= -53 dbm | V23: OK | W23: OK | X23: Bon | Y23: retransmission des trames HDLC*5
A24: 23 | B24: =AND(C24>=TODAY()-7, C24<=TODAY()-1) -> FALSE | C24: 45321 | D24: 0.47582176 | E24: 2021 | F24: 1207 | G24: M1 | H24: 1047 | I24: 35214500038727 | J24: Tanger/Casa | K24: 91.365 | L24: =VLOOKUP(K24,Liste!$L$2:$O$34,4,1) -> GSMR_16/17 | M24: N2 | N24: Ralentissement du train | O24: H.O complet entre 216 et 217,Bonne qualité /niveau de signal Requête de déconnexion a été envoyé par RBC | Q24: Signalisation | S24: H.O Complet entre 216 et217 | T24: dl Rxqual=0 | U24: dl rx level= -48 dbm | V24: OK | W24: OK | Y24: retransmission des trames HDLC*5
A25: 24 | B25: =AND(C25>=TODAY()-7, C25<=TODAY()-1) -> FALSE | C25: 45321 | D25: 0.33680556 | E25: 2009 | F25: 1209 | G25: M1 | H25: 7208 | I25: 35214500004427 | J25: Tanger/Casa | K25: 5.73 | L25: =VLOOKUP(K25,Liste!$L$2:$O$34,4,1) -> GSMR_02/03 | M25: N2 | N25: Arrêt du train | O25: ping pong entre 201 et 302 ,Bonne qualité de signal Requête de déconnexion a été envoyé par le RBC | Q25: BORD | S25: Ping pong entre 201 et 302 | T25: dl Rxqual=0 | U25: dl rx level= -48 dbm | V25: OK | W25: OK | X25: Mauvais | Y25: retransmission des trames HDLC*5
A26: 25 | B26: =AND(C26>=TODAY()-7, C26<=TODAY()-1) -> FALSE | C26: 45322 | D26: 0.49259259 | E26: 1017 | F26: 1212 | G26: M2 | H26: 1072 | I26: 35214500045424 | J26: Casa/Tanger | K26: 73.526 | L26: =VLOOKUP(K26,Liste!$L$2:$O$34,4,1) -> GSMR_13/14 | M26: N2 | N26: Ralentissement du train | O26: probléme de communication entre Bord et RBC , 4 requête train position envoyé par Bord Ho complèt entre 214 et 313 | Q26: Signalisation | R26: Remplacement de balise 510442-1 la nuit du 06-02 au 07/02 | S26: H.O Complet entre 314 et 213 | T26: dl Rxqual=3 | U26: dl rx level= -60 dbm | V26: OK | W26: NOK | X26: Mauvais | Y26: retransmission des trames HDLC*5
A27: 26 | B27: =AND(C27>=TODAY()-7, C27<=TODAY()-1) -> FALSE | C27: 45323 | D27: 0.40967593 | E27: 1009 | F27: 1209 | G27: M2 | H27: 1032 | I27: 35214500040638 | J27: Casa/Tanger | K27: 74.713 | L27: =VLOOKUP(K27,Liste!$L$2:$O$34,4,1) -> GSMR_13/14 | M27: N2 | N27: Ralentissement du train | O27: défaut de lecture Balise au point d'information 510442-1, HO non finalisé entre 314 et 313 | Q27: Signalisation | S27: H.O non finalisé entre 314 et 313 | T27: dl Rxqual=3 | U27: dl rx level= -71 dbm | V27: OK | W27: OK | X27: Bon | Y27: retransmission des trames HDLC*5
A28: 27 | B28: =AND(C28>=TODAY()-7, C28<=TODAY()-1) -> FALSE | C28: 45323 | D28: 0.66469907 | E28: 1033 | F28: 1209 | G28: M2 | H28: 1032 | I28: 35214500040638 | J28: Casa/Tanger | K28: 39.215 | L28: =VLOOKUP(K28,Liste!$L$2:$O$34,4,1) -> GSMR_07/08 | M28: N2 | N28: Ralentissement du train | O28: H.O non finalisé entre 308 et 307 , Bonne qualité/ niveau de signal , une requête déconnexion envoyé par le Bord | Q28: BORD | S28: H.O non finalisé entre 308 et 307 | T28: dl Rxqual=2 | U28: dl rx level= -65 dbm | V28: NOK | W28: OK | X28: Bon | Y28: retransmission des trames HDLC*5
A29: 28 | B29: =AND(C29>=TODAY()-7, C29<=TODAY()-1) -> FALSE | C29: 45324 | D29: 0.34760417 | E29: 2009 | F29: 1207 | G29: M1 | H29: 1046 | I29: 35214500038730 | J29: Casa/Tanger | K29: 70.144 | L29: =VLOOKUP(K29,Liste!$L$2:$O$34,4,1) -> GSMR_12/13 | M29: N2 | N29: Ralentissement du train | O29: H.O complet entre 312 et 213,Bonne qualité /niveau de signal Requête de déconnexion a été envoyé par RBC | Q29: RBC | R29: Remplacement de l'ensemble du circuit antennaire du GSM-R3/4 qui se compose de : IHM MONOMODE (Version 1M3) ;Tiroir Radio MONODE(Version 1M3);Cable Coaxial neuf ;Antenne GSM-R3/4 neuve<=> S08 | S29: H.O Complet entre 312 et 213 | T29: dl Rxqual=2 | U29: dl rx level= -60 dbm | V29: OK | W29: OK | X29: Mauvais | Y29: retransmission des trames HDLC*4
A30: 29 | B30: =AND(C30>=TODAY()-7, C30<=TODAY()-1) -> FALSE | C30: 45325 | D30: 0.94324074 | E30: 1061 | F30: 1205 | G30: M2 | H30: 1050 | I30: 35214500045357 | J30: Tanger/Casa | K30: 131.789 | L30: =VLOOKUP(K30,Liste!$L$2:$O$34,4,1) -> GSMR_23/24 | M30: N2 | N30: Ralentissement du train | O30: H.O complet entre 324 et 323,moyenne qualité de signal Requête de déconnexion a été envoyé par RBC | Q30: BORD | S30: H.O Complet entre 324 et 323 | T30: dl Rxqual=5 | U30: dl rx level= -77 dbm | V30: OK | W30: OK | X30: Mauvais | Y30: retransmission des trames HDLC*5
A31: 30 | B31: =AND(C31>=TODAY()-7, C31<=TODAY()-1) -> FALSE | C31: 45326 | D31: 0.47518519 | E31: 2021 | F31: 1208 | G31: M1 | H31: 1037 | I31: 35214500045488 | J31: Tanger/Casa | K31: 84.452 | L31: =VLOOKUP(K31,Liste!$L$2:$O$34,4,1) -> GSMR_15/16 | M31: N2 | N31: Ralentissement du train | O31: H.O complet entre 215 et 216,Bonne qualité /niveau de signal Requête de déconnexion a été envoyé par RBC | Q31: RBC/BORD | R31: Rame verifié durant la semaine S06 par smmrgv ; vswr bon ; puissance 37 ; 33 | S31: H.O Complet entre 215 et 216 | T31: dl Rxqual=3 | U31: dl rx level= -66 dbm | V31: OK | W31: OK | X31: Bon | Y31: retransmission des trames HDLC*5
A32: 31 | B32: =AND(C32>=TODAY()-7, C32<=TODAY()-1) -> FALSE | C32: 45327 | D32: 0.51060185 | E32: 2025 | F32: 1208 | G32: M1 | H32: 1036 | I32: 35214500045461 | J32: Tanger/Casa | K32: 45.829 | L32: =VLOOKUP(K32,Liste!$L$2:$O$34,4,1) -> GSMR_08/09 | M32: N2 | N32: Ralentissement du train | O32: H.O complet entre 207 et 208,Bonne qualité /niveau de signal Requête de déconnexion a été envoyé par RBC | Q32: Non specifie | R32: rame verifié Puissance 32,9 ; vswr bon | S32: H.O Complet entre 207 et 208 | T32: dl Rxqual=0 | U32: dl rx level= -51 dbm | V32: OK | W32: OK | X32: Mauvais | Y32: retransmission des trames HDLC*5
A33: 32 | B33: =AND(C33>=TODAY()-7, C33<=TODAY()-1) -> FALSE | C33: 45327 | D33: 0.32181713 | E33: 1001 | F33: 1206 | G33: M2 | H33: 1041 | I33: 35214500045477 | J33: Casa/Tanger | K33: 111.975 | L33: =VLOOKUP(K33,Liste!$L$2:$O$34,4,1) -> GSMR_20/21 | M33: N2 | N33: Ralentissement du train | O33: H.O complet entre 321 et 320,Bonne qualité /niveau de signal Requête de déconnexion a été envoyé par RBC | Q33: BORD | R33: En attente de verification de la chaine antennaire de la rame | S33: H.O Complet entre 321 et 320 | T33: dl Rxqual=0 | U33: dl rx level= -48 dbm | V33: OK | W33: OK | X33: Mauvais | Y33: retransmission des trames HDLC*5
A34: 33 | B34: =AND(C34>=TODAY()-7, C34<=TODAY()-1) -> FALSE | C34: 45327 | D34: 0.44409722 | E34: 1013 | F34: 1208 | G34: M2 | H34: 1045 | I34: 35214500045098 | J34: Casa/Tanger | K34: 125.206 | L34: =VLOOKUP(K34,Liste!$L$2:$O$34,4,1) -> GSMR_22/23 | M34: N2 | N34: Ralentissement du train | O34: H.O complet entre 323 et 222,Bonne qualité /niveau de signal Requête de déconnexion a été envoyé par RBC | Q34: GSMR | R34: Rame verifié par SMMRGV " Puissance 36,68 ; VSWR bon . Verification des tilts mecanique "bon" , switching des cartes radio " aucune amélioration" ; | S34: H.O Complet entre 323 et 222 | T34: dl Rxqual=0 | U34: dl rx level= -48 dbm | V34: OK | W34: OK | X34: Mauvais | Y34: retransmission des trames HDLC*5
A35: 34 | B35: =AND(C35>=TODAY()-7, C35<=TODAY()-1) -> FALSE | C35: 45327 | D35: 0.38385417 | E35: 2013 | F35: 1206 | G35: M1 | H35: 1054 | I35: 35214500022752 | J35: Tanger/Casa | K35: 26.739 | L35: =VLOOKUP(K35,Liste!$L$2:$O$34,4,1) -> GSMR_05/06 | M35: N2 | N35: Ralentissement du train | O35: H.O complet entre 205 et 206,Bonne qualité /niveau de signal Requête de déconnexion a été envoyé par RBC | Q35: BORD | R35: En attente de verification de la chaine antennaire de la rame | S35: H.O Complet entre 205 et 206 | T35: dl Rxqual=0 | U35: dl rx level= -62 dbm | V35: OK | W35: OK | X35: Mauvais | Y35: retransmission des trames HDLC*5
A36: 35 | B36: =AND(C36>=TODAY()-7, C36<=TODAY()-1) -> FALSE | C36: 45329 | D36: 0.44673611 | E36: 2017 | F36: 1211 | G36: M1 | H36: 1029 | I36: 35214500045449 | J36: Tanger/Casa | K36: 179.149 | L36: =VLOOKUP(K36,Liste!$L$2:$O$34,4,1) -> GSMR_30/31 | M36: N2 | N36: Ralentissement du train | O36: H.O Failure entre 330 et 331,Bonne qualité /niveau de signal Requête de déconnexion a été envoyé par le Bord | Q36: RBC | S36: H.O non finalisé entre 330 et 231 | T36: dl Rxqual=0 | U36: dl rx level= -68 dbm | V36: OK | W36: OK | X36: Bon | Y36: retransmission des trames HDLC*4
A37: 36 | B37: =AND(C37>=TODAY()-7, C37<=TODAY()-1) -> FALSE | C37: 45329 | D37: 0.76428241 | E37: 2049 | F37: 1209 | G37: M1 | H37: 1058 | I37: 35214500044293 | J37: Tanger/Casa | K37: 66.702 | L37: =VLOOKUP(K37,Liste!$L$2:$O$34,4,1) -> GSMR_12/13 | M37: N2 | N37: Ralentissement du train | O37: H.O complet entre 211 et 212,Bonne qualité /niveau de signal Requête de déconnexion a été envoyé par RBC | Q37: BORD | R37: dans l'attente de verification de la rame 1209 | S37: H.O Complet entre 211 et 212 | T37: dl Rxqual=0 | U37: dl rx level= -47 dbm | V37: OK | W37: OK | Y37: retransmission des trames HDLC*5
A38: 37 | B38: =AND(C38>=TODAY()-7, C38<=TODAY()-1) -> FALSE | C38: 45331 | D38: 0.94038194 | E38: 1061 | F38: 1212 | G38: M2 | H38: 1020 | I38: 35214500045494 | J38: Casa/Tanger | K38: 153.686 | L38: =VLOOKUP(K38,Liste!$L$2:$O$34,4,1) -> GSMR_26/27 | M38: N2 | N38: Arrêt du train | O38: H.O Failure entre 327 et 326,Bonne qualité /niveau de signal Requête de déconnexion a été envoyé par le RBC | Q38: BORD | R38: reverification de la rame 1212 M2 | S38: H.O non finalisé entre 327 et 326 | T38: dl Rxqual=0 | U38: dl rx level= -64 dbm | V38: OK | W38: OK | Y38: retransmission des trames HDLC*5
A39: 38 | B39: =AND(C39>=TODAY()-7, C39<=TODAY()-1) -> FALSE | C39: 45332 | D39: 0.7678125 | F39: 1203 | G39: M2 | H39: 1027 | J39: Casa/Tanger | K39: 186.87 | L39: =VLOOKUP(K39,Liste!$L$2:$O$34,4,1) -> GSMR_32/33 | M39: N2 | N39: Ralentissement du train | O39: H.O complet entre 234 et 233,Bonne qualité /niveau de signal Requête de déconnexion a été envoyé par RBC | Q39: RBC/BORD | R39: Des requêtes envoyé par le bord , aucune reponse cote RBC | S39: H.O Complet entre 234 et 233 | T39: dl Rxqual=2 | U39: dl rx level= -69 dbm | W39: NOK | Y39: retransmission des trames HDLC*5
A40: 39 | B40: =AND(C40>=TODAY()-7, C40<=TODAY()-1) -> FALSE | C40: 45332 | D40: 0.36259259 | E40: 1005 | F40: 1208 | G40: M2 | H40: 1045 | I40: 35214500045098 | J40: Casa/Tanger | K40: 111.975 | L40: =VLOOKUP(K40,Liste!$L$2:$O$34,4,1) -> GSMR_20/21 | M40: N2 | N40: Ralentissement du train | O40: H.O complet entre 321 et 320,Bonne qualité /niveau de signal Requête de déconnexion a été envoyé par RBC | Q40: BORD | R40: Ecart de la rame mauvais ; à verifier | S40: H.O Complet entre 321 et 320 | T40: dl Rxqual=0 | U40: dl rx level= -48 dbm | V40: OK | W40: OK | Y40: retransmission des trames HDLC*5
...

Sheet Dérangements N1 - LC
A1: N° ordre | B1: No Semaine | C1: Date | D1: Heure | E1: N° Train | F1: Rame | G1: Motrice / Cab | H1: Sens | I1: Km | J1: Evénement | K1: Description | L1: Motif | M1: Action
A2: 1 | B2: =WEEKNUM(C2,15) -> 16 | C2: 45761 | D2: 0.84305556 | E2: 2054 | F2: 1202 | G2: M1 | H2: Tanger/Casa | I2: 91.2 | J2: Arrêt du train | K2: Excès de vitesse, Groupe de balise incohérent, Avec arrêt d’urgence | L2: Reserve Travaux | M2: Traitement du point d'information par la solution d'impédance le 16/04
A3: 2 | B3: =WEEKNUM(C3,15) -> 17 | C3: 45770 | D3: 0.63333333 | E3: 1037 | F3: 1207 | G3: M2 | H3: Casa/Tanger | I3: 20.2 | J3: Arrêt du train | K3: Groupe de balise incohérent | L3: Responsabilité MOE, trancon de l'Installation non mis en service (hors perimetre infra) | M3: Signalé a MOE, verification de l'eurobalise et surveillance du passage de circulation
A4: 3 | B4: =WEEKNUM(C4,15) -> 17 | C4: 45771 | D4: 16:19:00 et 16:27:00 | E4: 2038 | F4: 1208 | G4: M1 | H4: Tanger/Casa | I4: 86,3 et 86,9 | J4: Arrêt du train | K4: Groupe de balise incohérent | L4: Reserve Travaux | M4: Traitement du point d'information par la solution d'impédance le 29/04
A5: 4 | B5: =WEEKNUM(C5,15) -> 21 | C5: 45794 | D5: 10h13 | E5: 1013 | F5: 1205 | G5: M2 | H5: Casa/Tanger | I5: 123.7 | J5: Arrêt du train | K5: signal répété fermé | L5: Reserve Travaux | M5: Traitement du point d'information par la solution d'impédance le jour meme, un mail a été adressé au MOE pour approfondir les investigations
A6: 5 | B6: =WEEKNUM(C6,15) -> 21 | C6: 45796 | D6: 16h57 | E6: 2034 2042 | F6: 1201 1203 | G6: M1 | H6: Tanger/Casa | I6: 86,7 et 86,45 86,5 et 86,8 | J6: Arrêt du train | K6: signal répété fermé | L6: Reserve Travaux | M6: Traitement du point d'information par la solution d'impédance le jour meme, un mail a été adressé au MOE pour approfondir les investigations
A7: 6 | B7: =WEEKNUM(C7,15) -> 21 | C7: 45798 | D7: 15h12 | E7: 2034 | F7: 1204 | G7: M1 | H7: Tanger/Casa | I7: 114.9 | J7: Arrêt du train | K7: signal répété fermé | L7: Reserve Travaux | M7: Traitement du point d'information par la solution d'impédance le jour meme, un mail a été adressé au MOE pour approfondir les investigations
A8: 7 | B8: =WEEKNUM(C8,15) -> 22 | C8: 45802 | D8: 17h00 | E8: 2042 | F8: 1207 | G8: M1 | H8: Tanger/Casa | I8: 121.3 | J8: Arrêt du train | K8: signal fermé | L8: Reserve Travaux | M8: Traitement du point d'information par la solution d'impédance le jour meme
A9: 8 | B9: =WEEKNUM(C9,15) -> 22 | C9: 28/05/2025 | D9: 10h35 | E9: 1009 | F9: 1208 | G9: M2 | H9: Casa/Tanger | I9: 121.3 | J9: Arrêt du train | K9: signal fermé | L9: Reserve Travaux | M9: Remplacement de l'eurobalise, et essai statique du signal
A10: 9 | B10: =WEEKNUM(C10,15) -> 22 | C10: 28/05/2025 | D10: 17h33 17h41 | E10: 2042 | F10: 1203 | G10: M1 | H10: Tanger/Casa | I10: 87,019 86,710 | J10: Arrêt du train | K10: signal fermé | L10: Reserve Travaux | M10: Traitement du point d'information par la solution d'impédance le jour meme
A11: 10 | B11: =WEEKNUM(C11,15) -> 22 | C11: 28/05/2025 | D11: 18h28 18h34 | E11: 2046 | F11: 1208 | G11: M1 | H11: Tanger/Casa | I11: 87,019 86,710 | J11: Arrêt du train | K11: signal fermé | L11: Reserve Travaux | M11: Remplacement de l'eurobalise, et essai statique du signal
A12: 11 | B12: =WEEKNUM(C12,15) -> 22 | C12: 29/05/2025 | D12: 19h21 19h29 | E12: 2050 | F12: 1208 | G12: M1 | H12: Tanger/Casa | I12: 86,800 86,500 | J12: Arrêt du train | K12: signal fermé | L12: Reserve Travaux | M12: En cours d'investigation, attente retour alstom
A13: 12 | B13: =WEEKNUM(C13,15) -> 23 | C13: 45809 | D13: 12h23 12h27 | E13: 2022 | F13: 1203 | G13: M1 | H13: Tanger/Casa | I13: 95+100 94+950 | J13: Arrêt du train | K13: signal Fermé (avec déclenchement alerte radio) | L13: Elément de sectionnement BRB défectueux, bon après remplacement et essai statique | M13: Remplacement de l'element de sectionement defectueux
A14: 13 | B14: =WEEKNUM(C14,15) -> 25 | C14: 45823 | D14: 20h41 | E14: 2054 | F14: 1208 | G14: M1 | H14: Tanger/Casa | I14: 86+700 | J14: Arrêt du train | K14: Signal fermé | L14: 22h30 : Balise fonctionne normale après passage plusieurs circulation | M14: Investigations en cours avec ALSTOM (La solution d'impedence est installée, l'essai statique de l'eurobalise RAS)
A15: 14 | B15: =WEEKNUM(C15,15) -> 27 | C15: 45837 | D15: 15h37 20h43 21h36 | E15: 2034 2054 2058 | F15: 1201 1208+1202 1201 | G15: M1 | H15: Tanger/Casa | I15: 87+600 | J15: Arrêt du train | K15: signal fermé | L15: Reserve Travaux | M15: raccordement à la terre du câble 3NSS, PI toujours sous surveillance
A16: 15 | B16: =WEEKNUM(C16,15) -> 27 | C16: 45838 | D16: 16h32 | E16: 2038 | F16: 1201 | G16: M1 | H16: Tanger/Casa | I16: 86+700 86+450 | J16: Arrêt du train | K16: signal fermé | L16: Reserve Travaux
A17: 16 | B17: =WEEKNUM(C17,15) -> 27 | C17: 45838 | D17: 19h16 21h40 | E17: 1045 1057 | F17: 1204/1211 1209 | G17: M1 | H17: Tanger/Casa | I17: 115+100 | J17: Arrêt du train | K17: Groupe de balise incohérent « Train trip » | L17: en cours | M17: Traitement du point d'information par la solution d'impédance est prévu le 07/05.
A18: 17 | B18: =WEEKNUM(C18,15) -> 28 | C18: 45845 | D18: 19h30 | E18: 2050 | F18: 1210 | G18: M1 | H18: Tanger/Casa | I18: 86+700 86+500 86+800 | J18: Arrêt du train | K18: signal fermé | L18: Bon après vérification et serrage des connecteurs de la zone sur le terrain. Installation reste sous surveillance. Pour le signal 114+76 les investigations sont en cours | M18: En attente d'un retour de la part Alstom, un FAX est en cours de traitement par la DMI pour envoi à Alstom
A19: 18 | B19: =WEEKNUM(C19,15) -> 29 | C19: 45852 | D19: 17h29 | E19: 2042 | F19: 1206 | G19: M1 | H19: Tanger/Casa | I19: 86+500 86+800 | J19: Arrêt du train | K19: signal fermé | L19: 19h30 : Bon après changement d’émetteur de zone adjacente 87.8 v2 par TU de zone 116.19 | M19: En attente d'un retour de la part d'Alstom
A20: 19 | B20: =WEEKNUM(C20,15) -> 34 | C20: 45888 | D20: 18h24 | E20: 2046 | G20: M1 | H20: Tanger/Casa | I20: 87+500 | J20: Arrêt du train | K20: Groupe de balise incohérent « Train trip » | L20: A 20h00 balise fonctionnelle après passage des circulation RAS
A21: 20 | B21: =WEEKNUM(C21,15) -> 35 | C21: 45894 | D21: 23h36 | E21: 2082 | F21: 1202 | G21: M1 | H21: Tanger/Casa | I21: 84+450 | J21: Arrêt du train | K21: signal fermé | L21: Bon après passage de circulation | M21: En attente d'un retour de la part d'Alstom
A22: 21 | B22: =WEEKNUM(C22,15) -> 35 | C22: 45895 | D22: 17h13 | E22: 2038 | F22: 1209 | G22: M1 | H22: Tanger/Casa | I22: 14+500 | J22: Arrêt du train | K22: Groupe de balise incohérent « Train trip » | L22: en cours
A23: 22 | B23: =WEEKNUM(C23,15) -> 36 | C23: 45899 | D23: 18h41 | E23: 2042 | F23: 1202 | G23: M1 | H23: Tanger/Casa | I23: 27+700 | J23: Arrêt du train | K23: Groupe de balise incohérent « Train trip » | L23: Intervention SE terminé à 20h35
A24: 23 | B24: =WEEKNUM(C24,15) -> 36 | C24: 45900 | D24: 12h57 | E24: 2022 | F24: 1207 | G24: M1 | H24: Tanger/Casa | I24: 25+300 | J24: Arrêt du train | K24: Groupe de balise incohérent « Train trip » | L24: 13h30 Bon après désactivation de group balise
A25: 24 | B25: =WEEKNUM(C25,15) -> 37 | C25: 45906 | D25: 05h00 | E25: 15335 | F25: 1204 | G25: M2 | H25: Casa/Tanger | I25: 86+400 | J25: Arrêt du train | K25: Groupe de balise incohérent « Train trip » | L25: 07h30 bon après passage deuxième circulation
A26: 25 | B26: =WEEKNUM(C26,15) -> 39 | C26: 45921 | D26: 15h30 | E26: 2034 | F26: 1205 | G26: M2 | H26: Casa/Tanger | I26: 114+700 | J26: Arrêt du train | K26: Groupe de Balise Rencontré en rouge | L26: 17h10, Bon après passage de trois circulations | M26: L’analyse des logs de l’enclenchement n’a révélé aucun dysfonctionnement. Une demande a été transmise à ALSTOM afin d’approfondir les investigations.
A27: 26 | B27: =WEEKNUM(C27,15) -> 39 | C27: 45922 | D27: 15h30 | E27: 1033 | G27: M1 | H27: Tanger/Casa | I27: 123+400 | J27: Arrêt du train | K27: O.S | L27: 16h30, Bon après passage du 2eme train, RAS après vérification | M27: après analyse des logs de l'enclenchement, une perte fugitive de communication entre la carte TEBD et l'eurobalise a été constaté, action corrective : rearmement de la carte TEBD et surveillance de l'installation
A28: 27 | B28: =WEEKNUM(C28,15) -> 41 | C28: 45935 | D28: 22h17 | E28: 1061 | F28: 1211 | G28: M1 | H28: Tanger/Casa | I28: 111+200 | J28: Arrêt du train | K28: un signal répété fermé | L28: Installation fonctionne normale bon après vérification | M28: Le Point d'information a été surveillé, pas d'anomalie détéctée
A29: 28 | B29: =WEEKNUM(C29,15) -> 43 | C29: 45947 | D29: 16h17 | E29: 2038 | F29: 1209 | G29: M2 | H29: Casa/Tanger | I29: 99+400 | J29: Arrêt du train | K29: Sur vitesse / acquittement de l’OS | L29: Balise fonctionne normale bon après passage du train
A30: 29 | B30: 44 | C30: 45956 | D30: 05h49 | E30: 15439 | G30: M1 | H30: Tanger/Casa | I30: 116.25 | J30: Arrêt du train | K30: Groupe de balise incohérent « Train trip » | L30: 07h30 Mauvais contact au niveau de BRB bon après remise en état
A31: 30 | B31: 45 | C31: 45966 | D31: 14h21 | E31: 1037 | F31: 1209 | G31: M2 | H31: Casa/Tanger | I31: 110+600 | J31: Arrêt du train | K31: Sur vitesse L’OS | L31: Le signal 110.6 a été répeté fermé lors du passage de train. | M31: Balise déja équipé par la soulution d'impédence proposé par ALSTOM, le comportement du PI a été surveillé pendant le passage de trois circulation
A32: 31 | B32: 47 | C32: 45980 | D32: 22h17 | E32: 1061 | F32: 1209 | G32: M2 | H32: Casa/Tanger | I32: 110+600 | J32: Arrêt du train | K32: un signal répété fermé | L32: Bon après essai de commutation au niveau de balise du signal 110.6 V1I
A33: 32 | B33: 50 | C33: 46001 | D33: 19h25 | E33: 1049 | F33: 1207 | G33: M1 | H33: Tanger/Casa | I33: 111+300 | J33: Arrêt du train | K33: Sémaphore au lieu VL au niveau ETCS | L33: rétabli à 20h30 après passage du deuxième train 20h30
A34: 33 | B34: 50 | C34: 46004 | D34: 17h18 | E34: 1041 | F34: 1204 | G34: M1 | H34: Tanger/Casa | I34: 116+57 | J34: Arrêt du train | K34: Voie libre répeté fermé | L34: 18h30 Bon après passage du deuxième train | M34: Pas d'anomalie detecté par l'équipe, bon après passage de la deuxieme circulation
A35: 34 | B35: 51 | C35: 44182 | D35: 21h10 | E35: 1061 | F35: 1205 | G35: M1 | H35: Tanger/Casa | I35: 13+800 | J35: Arrêt du train | K35: Groupe de balise incohérent | L35: Bon après passage circulation | M35: Trancon non exploité de l'ETCS N1
A36: 35 | B36: 51 | C36: 46009 | D36: 06h12 | E36: 1001 | F36: 1201 | G36: M1 | H36: Tanger/Casa | I36: 13+200 | J36: Arrêt du train | K36: Groupe de balise incohérent | L36: 10h00 Bon après couverture de la balise au km 13+50
A37: 36 | B37: 51 | C37: 46009 | D37: 07h10 | E37: 1005 | F37: 1210 | G37: M1 | H37: Tanger/Casa | I37: 13+300 | J37: Arrêt du train | K37: Groupe de balise incohérent | L37: 10h00 Bon après couverture de la balise au km 13+50
A38: 37 | B38: 51 | C38: 46009 | D38: 08h20 | E38: 1009 | F38: 1206 | G38: M1 | H38: Tanger/Casa | I38: 13+200 | J38: Arrêt du train | K38: Groupe de balise incohérent | L38: 10h00 Bon après couverture de la balise au km 13+50
A39: 38 | B39: 52 | C39: 46016 | D39: 18h10 | E39: 2042 | F39: 1203 | G39: M2 | H39: Casa/Tanger | I39: 12+100 | J39: Arrêt du train | K39: Groupe de balise incohérent | L39: Bon après passage circulation | M39: Trancon non exploité de l'ETCS N1
A40: 39 | B40: 52 | C40: 46016 | D40: 19h03 | E40: 2046 | F40: 1201 | G40: M2 | H40: Casa/Tanger | I40: 12+000 | J40: Arrêt du train | K40: Groupe de balise incohérent | L40: 10h00 Bon après couverture de la balise au km 12
...

Sheet Liste
A1: cause_racine | B1: Rame | C1: Contributeurs | E1: Motrice | G1: Parcours | L1: début | M1: fin | N1: Interavlle | O1: Sites GSM-R | Q1: Rame | R1: Sous Systeme | V1: Evenement
A2: Bord | B2: 1201 | C2: C/R GSM-R | E2: M1 | G2: Tanger/Casa | H2: Tanger/Casa | I2: 2081/2082 | L2: 2.26 | M2: 3.69 | N2: =L2&" - "&M2 -> 2,26 - 3,69 | O2: GSMR_01/02 | Q2: 1201 | R2: BORD | S2: SGHAYER Achraf | T2: M1 | U2: Bon | V2: Ralentissement du train
A3: RBC | B3: 1202 | C3: Alstom | E3: M2 | G3: Casa/Tanger | I3: 2001/2002 | L3: 3.691 | M3: 9.641 | N3: =L3&" - "&M3 -> 3,691 - 9,641 | O3: GSMR_02/03 | Q3: 1202 | R3: GSMR | S3: ELHAJOUIA Achraf | T3: M2 | U3: Moyen | V3: Arrêt du train
A4: GSM-R | B4: 1203 | C4: AMI LGV | I4: 2005/2006 | L4: 9.642 | M4: 17.457 | N4: =L4&" - "&M4 -> 9,642 - 17,457 | O4: GSMR_03/04 | Q4: 1203 | R4: BORD/GSMR | S4: ISMALI ALAOUI Hamza | U4: Mauvais
A5: RBC/Bord | B5: 1204 | C5: AMI CCR SIG | I5: 2009/2010 | L5: 17.458 | M5: 23.557 | N5: =L5&" - "&M5 -> 17,458 - 23,557 | O5: GSMR_04/05 | Q5: 1204 | R5: RBC | S5: Fahd OUSSALH
A6: RBC/GSM-R | B6: 1205 | C6: AMI CCR GSMR | I6: 2013/2014 | L6: 23.558 | M6: 29.849 | N6: =L6&" - "&M6 -> 23,558 - 29,849 | O6: GSMR_05/06 | Q6: 1205 | R6: RBC/GSMR | S6: HARIRI Bahaeddine
A7: GSM-R/Bord | B7: 1206 | C7: SMMRGV | I7: 2017/2018 | L7: 29.85 | M7: 36.337 | N7: =L7&" - "&M7 -> 29,85 - 36,337 | O7: GSMR_06/07 | Q7: 1206 | R7: RBC/BORD | S7: Saad Elhabib
A8: Externe | B8: 1207 | C8: Huawei | I8: 2021/2022 | L8: 36.338 | M8: 43.037 | N8: =L8&" - "&M8 -> 36,338 - 43,037 | O8: GSMR_07/08 | Q8: 1207 | R8: NA | S8: Oussama ZEHOUANI
A9: GSM-R/RBC | B9: 1208 | C9: Thalès | I9: 2029/2030 | L9: 43.038 | M9: 49.318 | N9: =L9&" - "&M9 -> 43,038 - 49,318 | O9: GSMR_08/09 | Q9: 1208 | S9: Nassim NAJIM
A10: Signalisation | B10: 1209 | C10: Huawei/Thalès | I10: 2025/2026 | L10: 49.319 | M10: 55.174 | N10: =L10&" - "&M10 -> 49,319 - 55,174 | O10: GSMR_09/10 | Q10: 1209 | S10: ELGUEZZAR Anas
B11: 1210 | C11: Tous | I11: 2033/2034 | L11: 55.175 | M11: 60.163 | N11: =L11&" - "&M11 -> 55,175 - 60,163 | O11: GSMR_10/11 | Q11: 1210 | S11: MAROUANI Otmane
B12: 1211 | I12: 2037/2038 | L12: 60.164 | M12: 66.628 | N12: =L12&" - "&M12 -> 60,164 - 66,628 | O12: GSMR_11/12 | Q12: 1211 | S12: HAMZAOUI Youssef
B13: 1212 | I13: 2041/2042 | L13: 66.629 | M13: 71.311 | N13: =L13&" - "&M13 -> 66,629 - 71,311 | O13: GSMR_12/13 | Q13: 1212 | S13: LAGDEM Elmehdi
I14: 2045/2046 | L14: 71.312 | M14: 76.474 | N14: =L14&" - "&M14 -> 71,312 - 76,474 | O14: GSMR_13/14 | Q14: Tanger/Casa | S14: Noura MOUSSAOUI
I15: 2049/2050 | L15: 76.475 | M15: 80.728 | N15: =L15&" - "&M15 -> 76,475 - 80,728 | O15: GSMR_14/15 | Q15: Casa/Tanger | S15: Aymane ASSAL
I16: 2053/2054 | L16: 80.729 | M16: 85.772 | N16: =L16&" - "&M16 -> 80,729 - 85,772 | O16: GSMR_15/16 | S16: Mohamed rida SAFRI
I17: 2057/2058 | L17: 85.773 | M17: 92.59 | N17: =L17&" - "&M17 -> 85,773 - 92,59 | O17: GSMR_16/17
I18: 2061/2062 | L18: 92.591 | M18: 99.59 | N18: =L18&" - "&M18 -> 92,591 - 99,59 | O18: GSMR_17/18
I19: 10071/10072 | L19: 99.591 | M19: 105.347 | N19: =L19&" - "&M19 -> 99,591 - 105,347 | O19: GSMR_18/19
H20: Casa/Tanger | I20: 1081/1082 | L20: 105.348 | M20: 111.452 | N20: =L20&" - "&M20 -> 105,348 - 111,452 | O20: GSMR_19/20
I21: 1001/1002 | L21: 111.453 | M21: 118.92 | N21: =L21&" - "&M21 -> 111,453 - 118,92 | O21: GSMR_20/21
I22: 1005/1006 | L22: 118.921 | M22: 124.35 | N22: =L22&" - "&M22 -> 118,921 - 124,35 | O22: GSMR_21/22
I23: 1009/1010 | L23: 124.351 | M23: 128.97 | N23: =L23&" - "&M23 -> 124,351 - 128,97 | O23: GSMR_22/23
I24: 1013/1014 | L24: 128.971 | M24: 136.647 | N24: =L24&" - "&M24 -> 128,971 - 136,647 | O24: GSMR_23/24
I25: 1017/1018 | L25: 136.648 | M25: 143.22 | N25: =L25&" - "&M25 -> 136,648 - 143,22 | O25: GSMR_24/25
I26: 1021/1022 | L26: 143.221 | M26: 151.02 | N26: =L26&" - "&M26 -> 143,221 - 151,02 | O26: GSMR_25/26
I27: 1025/1026 | L27: 151.021 | M27: 157.53 | N27: =L27&" - "&M27 -> 151,021 - 157,53 | O27: GSMR_26/27
I28: 1029/1030 | L28: 157.531 | M28: 163.424 | N28: =L28&" - "&M28 -> 157,531 - 163,424 | O28: GSMR_27/28
I29: 1033/1034 | L29: 163.425 | M29: 168.75 | N29: =L29&" - "&M29 -> 163,425 - 168,75 | O29: GSMR_28/29
I30: 1037/1038 | L30: 168.751 | M30: 174.54 | N30: =L30&" - "&M30 -> 168,751 - 174,54 | O30: GSMR_29/30
I31: 1041/1042 | L31: 174.541 | M31: 182.85 | N31: =L31&" - "&M31 -> 174,541 - 182,85 | O31: GSMR_30/31
I32: 1045/1046 | L32: 182.851 | M32: 185.07 | N32: =L32&" - "&M32 -> 182,851 - 185,07 | O32: GSMR_31/32
I33: 1049/1050 | L33: 185.071 | M33: 187.232 | N33: =L33&" - "&M33 -> 185,071 - 187,232 | O33: GSMR_32/33
I34: 1053/1054 | L34: 187.233 | N34: =L34&" - "&M34 -> 187,233 - | O34: GSMR_33/RAC
I35: 1057/1058
I36: 1061/1062
I37: 10075/10076

Sheet Retard train
A1: N° ordre | B1: Date | C1: Heure | D1: N° Train | E1: Rame | F1: Motrice / Cab | G1: MRM | H1: Sens | I1: Km | J1: Intervalle | K1: Temps Perdu | L1: Evénement | M1: Cause_racine | N1: Sous Système mis en cause | O1: Traces ABIS A fournir par Huawei | P1: Traces RBC A fournir par AMI CCR | Q1: Traces Expandium (GSMR) A fournir par GSMR | R1: Fichier MRU | S1: Action | T1: Execution HO | U1: RxQual | V1: RxLev | W1: Voisinage (10sec) | X1: Com DTE-DCE | Y1: Retransmission trames HDLC/T.70 | Z1: Alarmes BTS | AA1: CIRE | AB1: CIERS | AC1: Acquittement AUC | AD1: BUG RBC | AE1: Liens PAI | AF1: Temps perdu2 | AG1: Pilote | AH1: Échéance
A2: 1 | B2: 45304 | C2: 0.64375 | D2: 2037 | E2: 1203 | F2: M1 | G2: 1024 | H2: Tanger/Casa | I2: 104 | J2: =VLOOKUP(I2,Liste!$L$2:$O$34,4,1) -> GSMR_18/19 | K2: 14 | L2: arrêt du train suite à un message de défaut " arrêt d'urgence inconditionnel" sur l'IHM aux alentours du site 18-19 | M2: aucune déconnexion | O2: à fournir | P2: à fournir | Q2: Fait | R2: Fait
A3: 2 | B3: 45328 | C3: 0.51805556 | D3: 2025 | E3: 1204 | F3: M1 | H3: Tanger/Casa | I3: 99.18 | J3: =VLOOKUP(I3,Liste!$L$2:$O$34,4,1) -> GSMR_17/18 | K3: 13 | L3: arrêt du train suite à une perte de liaison entre RBC et PAI | M3: aucune déconnexion | O3: à fournir | P3: à fournir | R3: à fournir
A4: 3 | B4: 45327 | C4: 0.86118056 | D4: 1053 | E4: 1207 | F4: M2 | G4: 1008 | H4: Casa/Tanger | I4: 119.867 | J4: =VLOOKUP(I4,Liste!$L$2:$O$34,4,1) -> GSMR_21/22 | K4: 1 | L4: RAS | M4: H.O complet entre 222 et 321,Bonne qualité /niveau de signal Requête de déconnexion a été envoyé par RBC | O4: à fournir | P4: à fournir | Q4: Fait | R4: à fournir | T4: H.O Complet entre 222 et 321 | U4: dl Rxqual=0 | V4: dl rx level= -48 dbm | X4: OK | Y4: retransmission des trames HDLC*5
A5: 4 | B5: 45332 | C5: 0.34011574 | D5: 2009 | E5: 1203 | F5: M1 | G5: 1025 | H5: Tanger/Casa | I5: 17.59 | J5: =VLOOKUP(I5,Liste!$L$2:$O$34,4,1) -> GSMR_04/05 | M5: H.O complet entre 203 et 204,Bonne qualité /niveau de signal Requête de déconnexion a été envoyé par RBC | P5: à fournir | Q5: à fournir | U5: H.O Complet entre 203 et 204 | V5: dl Rxqual=1 | W5: dl rx level= -56 dbm | X5: OK | Y5: retransmission des trames HDLC*5
A6: 66 | B6: 45342 | C6: 0.46150463 | D6: 2021 | E6: 1208 | F6: M1 | G6: 1037 | H6: Tanger/Casa | I6: 5.73 | J6: =VLOOKUP(I6,Liste!$L$2:$O$34,4,1) -> GSMR_02/03 | L6: Echec de connexion supervision radio ayant causé un arrêt de train , | M6: un problème au niveau des deux cartes DDPU du site GSM-R 2 | N6: incide | P6: à fournir | Q6: à fournir | R6: à fournir | Y6: retransmission des trames HDLC*5
A7: 67 | B7: 45342 | C7: 0.50359954 | D7: 2025 | E7: 1211 | F7: M1 | G7: 1029 | H7: Tanger/Casa | I7: 4.707 | J7: =VLOOKUP(I7,Liste!$L$2:$O$34,4,1) -> GSMR_02/03 | L7: Echec de connexion supervision radio ayant causé un arrêt de train , | M7: un problème au niveau des deux cartes DDPU du site GSM-R 2 | P7: à fournir | Q7: à fournir | R7: à fournir | Y7: retransmission des trames HDLC*5
A8: 68 | B8: 45369 | C8: 0.75326389 | E8: 1206 | F8: M2 | G8: 1040 | H8: Casa/Tanger | I8: 7.321 | J8: =VLOOKUP(I8,Liste!$L$2:$O$34,4,1) -> GSMR_02/03 | L8: Echec de connexion supervision radio ayant causé un Arret de Train post Trip | M8: H.O non finalisé entre 203 et 302, Mauvaise qualité de signal ,Requête de déconnexion a été envoyé par RBC | P8: à fournir | Q8: à fournir | R8: à fournir | T8: H.O non Finalisé entre 203 et 302 | U8: dl Rxqual=7 | V8: dl rx level= -65 dbm | W8: OK | X8: OK | Y8: retransmission des trames HDLC*5
A9: 117 | B9: 45381 | C9: 0.37819444 | D9: 2013 | E9: 1209 | F9: M1 | G9: 7208 | H9: Tanger/Casa | I9: 4.707 | J9: GSMR_02/03 | L9: Echec de connexion supervision radio ayant causé un Arret de Train En FS | N9: GSM-R | O9: à fournir | P9: à fournir | Q9: à fournir | R9: à fournir | S9: Analyse Spéctrale Prévu le 16/04/2024 | T9: H.O complet entre 201 et 302 | U9: dl Rxqual=6 | V9: dl rx level= -48 dbm | W9: OK | X9: OK | Y9: retransmission des trames HDLC*5
A10: 129 | B10: 45389 | C10: 0.64518519 | D10: 2037 | E10: 1211 | F10: M1 | G10: 1028 | H10: Tanger/Casa | I10: 92.561 | J10: GSMR_16/17 | K10: 4 | L10: Echec de connexion supervision radio ayant causé un Arret de Train post Trip | N10: BORD | O10: à fournir | P10: à fournir | Q10: à fournir | R10: à fournir | T10: H.O complet entre 215 et 216 | U10: dl Rxqual=0 | V10: dl rx level= -62 dbm | W10: OK | X10: OK | Y10: retransmission des trames HDLC*5
A11: 130 | B11: 45390 | C11: 0.58732639 | D11: 1025 | E11: 1209 | F11: M2 | G11: 1033 | H11: Casa/Tanger | I11: 7.321 | J11: GSMR_02/03 | K11: 5 | L11: Echec de connexion supervision radio ayant causé un Arret de Train En FS | N11: GSM-R | P11: à fournir | Q11: à fournir | R11: à fournir | S11: analyse Spéctrale Prévu | T11: H.O non Finalisé entre 303 et 202 | U11: dl Rxqual=6 | V11: dl rx level= -55 dbm | W11: OK | X11: OK | Y11: retransmission des trames HDLC*4
A12: 140 | B12: 45396 | C12: 0.30340278 | D12: 10075 | E12: 1201 | F12: M2 | G12: 1025 | H12: Casa/Tanger | I12: 125.206 | J12: GSMR_22/23 | L12: Echec de connexion supervision radio ayant causé un Arret de Train En mode Post trip | N12: Bord/RBC | P12: à fournir | Q12: à fournir | R12: à fournir | S12: on attendant croisement des traces JRU | T12: H.O complet entre 223 et 322 | U12: dl Rxqual=0 | V12: dl rx level= -78 dbm | W12: OK | X12: OK | Y12: retransmission des trames HDLC*5
A13: 149 | B13: 45403 | C13: 0.63822917 | D13: 2037 | E13: 1203 | F13: M1 | G13: 1025 | H13: Tanger/Casa | I13: 56.555 | J13: GSMR_10/11 | K13: - | L13: Echec de connexion supervision radio ayant causé un Arret de Train | N13: BORD | P13: à fournir | Q13: à fournir | R13: à fournir | S13: verification de la chaine antennaire | T13: H.O complet entre 209 et 210 | U13: dl Rxqual=5 | V13: dl rx level= -54 dbm | W13: OK | X13: OK | Y13: retransmission des trames HDLC*5
A14: 151 | B14: 45405 | C14: 0.54042824 | D14: 1021 | E14: 1208 | F14: M2 | G14: 1045 | H14: Casa/Tanger | I14: 35.016 | J14: GSMR_06/07 | K14: - | L14: Echec de connexion supervision radio ayant causé un Arret de Train mode Trip | N14: BORD | P14: à fournir | Q14: à fournir | R14: à fournir | S14: verification de la chaine antennaire | T14: H.O complet entre 208 et 307 | U14: dl Rxqual=2 | V14: dl rx level= -67 dbm | W14: OK | X14: OK | Y14: retransmission des trames HDLC*5
A15: 153 | B15: 45406 | C15: 0.41353009 | D15: 1009 | E15: 1205 | F15: M2 | G15: 1035 | H15: Casa/Tanger | I15: 78.155 | J15: GSMR_14/15 | K15: - | L15: Echec de connexion supervision radio ayant causé un Arret de Train mode Trip | N15: BORD | P15: à fournir | Q15: à fournir | R15: à fournir | S15: verification de la chaine antennaire | T15: H.O complet entre 315 et 314 | U15: dl Rxqual=0 | V15: dl rx level= -61 dbm | W15: OK | X15: OK | Y15: retransmission des trames HDLC*5
A16: 157 | B16: 45407 | C16: 0.58671296 | D16: 1025 | E16: 1208 | F16: M2 | G16: 1044 | H16: Casa/Tanger | I16: 7.321 | J16: GSMR_02/03 | K16: 4 | L16: Echec de connexion supervision radio ayant causé un Arret de Train | N16: GSMR/BORD | P16: à fournir | Q16: à fournir | R16: à fournir | S16: Attente analyse spectrale | T16: H.O Complet entre 303 et 202 | U16: dl Rxqual=7 | V16: dl rx level= -75 dbm | W16: OK | X16: OK | Y16: retransmission des trames HDLC*5
A17: 159 | B17: 45407 | C17: 0.83627315 | D17: 1049 | E17: 1209 | F17: M2 | G17: 1033 | H17: Casa/Tanger | I17: 7.321 | J17: GSMR_02/03 | K17: 4 | L17: Echec de connexion supervision radio ayant causé un Arret de Train | N17: GSMR/BORD | P17: à fournir | Q17: à fournir | R17: à fournir | S17: Attente analyse spectrale | T17: H.O Complet entre 303 et 302 | U17: dl Rxqual=7 | V17: dl rx level= -72 dbm | W17: OK | X17: OK | Y17: retransmission des trames HDLC*5
A18: 161 | B18: 45408 | C18: 0.9027662 | D18: 1058 | E18: 1202 | F18: M2 | G18: 1023 | H18: Casa/Tanger | I18: 143.112 | J18: GSMR_24/25 | L18: Echec de connexion supervision radio ayant causé un Arret de Train | N18: BORD | P18: à fournir | Q18: à fournir | R18: à fournir | S18: verification de la chaine antennaire | T18: H.O Complet entre 326 et 325 | U18: dl Rxqual=2 | V18: dl rx level= -70 dbm | W18: OK | X18: OK | Y18: retransmission des trames HDLC*5
A19: 176 | B19: 45418 | C19: 0.72407407 | D19: 2045 | E19: 1205 | F19: M1 | G19: 7217 | H19: Tanger/Casa | I19: 79.282 | J19: GSMR_14/15 | L19: Echec de connexion supervision radio ayant causé un Arret de Train | N19: BORD | P19: à fournir | Q19: à fournir | R19: à fournir | S19: en attente rapport du conducteur | T19: H.O Complet entre 214 et 215 | U19: dl Rxqual=0 | V19: dl rx level= -56 dbm | W19: OK | X19: NOK | Y19: retransmission des trames HDLC*5
A20: 177 | B20: 45419 | C20: 0.25769676 | D20: 1081 | E20: 1203 | F20: M2 | G20: 1027 | H20: Casa/Tanger | I20: 151.35 | J20: GSMR_26/27 | L20: Echec de connexion supervision radio ayant causé un Arret de Train | N20: BORD | P20: à fournir | Q20: à fournir | R20: à fournir | S20: en attente d'instoration des filtres | T20: H.O Complet entre 327 et 326 | U20: dl Rxqual=0 | V20: dl rx level= -48 dbm | W20: OK | X20: OK | Y20: retransmission des trames HDLC*5
A21: 182 | B21: 45420 | C21: 0.96346065 | D21: 1053 | E21: 1201 | F21: M2 | G21: 1060 | H21: Casa/Tanger | I21: 7.321 | J21: GSMR_02/03 | L21: Echec de connexion supervision radio ayant causé un Arret de Train | N21: GSMR/BORD | P21: à fournir | Q21: à fournir | R21: à fournir | S21: en attente d'instoration des filtres | T21: H.O non finalisé entre 303 et 202 | U21: dl Rxqual=7 | V21: dl rx level= -54 dbm | W21: OK | X21: OK | Y21: retransmission des trames HDLC*5
A22: 185 | B22: 45421 | C22: 0.87877315 | D22: 2061 | E22: 1207 | F22: M1 | G22: 1046 | H22: Tanger/Casa | I22: 6.13 | J22: GSMR_02/03 | L22: Echec de connexion supervision radio ayant causé un Arret de Train | N22: GSMR/BORD | P22: à fournir | Q22: à fournir | R22: à fournir | S22: en attente d'instoration des filtres | T22: H.O non finalisé entre 302 et 203 | U22: dl Rxqual=7 | V22: dl rx level= -52 dbm | W22: OK | X22: OK | Y22: retransmission des trames HDLC*5
A23: 187 | B23: 45423 | C23: 0.31611111 | D23: 2005 | E23: 1211 | F23: M1 | G23: 1029 | H23: Tanger/Casa | I23: 144.326 | J23: GSMR_25/26 | L23: Echec de connexion supervision radio ayant causé un Arret de Train | N23: BORD | P23: à fournir | Q23: à fournir | R23: à fournir | S23: en attente décision de remplacement CAB Radio | T23: H.O Complet entre 224 et 225 | U23: dl Rxqual=0 | V23: dl rx level= -68 dbm | W23: OK | X23: OK | Y23: retransmission des trames HDLC*5
A24: 189 | B24: 45423 | C24: 0.58097222 | D24: 1025 | E24: 1205 | F24: M2 | G24: 1034 | H24: Casa/Tanger | I24: 74.713 | J24: GSMR_13/14 | L24: Echec de connexion supervision radio ayant causé un Arret de Train | N24: BORD | P24: à fournir | Q24: à fournir | R24: à fournir | S24: en attente décision de remplacement CAB Radio | T24: H.O Complet entre 313 et 314 | U24: dl Rxqual=0 | V24: dl rx level= -58 dbm | W24: OK | X24: OK | Y24: Pas de retransmission des trames HDLC
A25: 190 | B25: 45423 | C25: 0.69042824 | D25: 1037 | E25: 1202 | F25: M2 | G25: 1022 | H25: Casa/Tanger | I25: 153.686 | J25: GSMR_26/27 | K25: 6 | L25: Echec de connexion supervision radio ayant causé un Arret de Train | N25: BORD | P25: à fournir | Q25: à fournir | R25: à fournir | S25: en attente décision de remplacement CAB Radio | T25: H.O non finalisé entre 327 et 326 | U25: dl Rxqual=5 | V25: dl rx level= -66 dbm | W25: NOK | X25: OK | Y25: retransmission des trames HDLC*5
A26: 194 | B26: 45424 | C26: 0.79530093 | D26: 2053 | E26: 1207 | F26: M1 | G26: 1047 | H26: Tanger/Casa | I26: 6.13 | J26: GSMR_02/03 | L26: Echec de connexion supervision radio ayant causé un Arret de Train | N26: BORD | P26: à fournir | Q26: à fournir | R26: à fournir | S26: en attente décision de remplacement CAB Radio | T26: H.O non finalisé entre 203 et 301 | U26: dl Rxqual=7 | V26: dl rx level= -65 dbm | W26: OK | X26: OK | Y26: retransmission des trames HDLC*5
A27: 212 | B27: 45435 | C27: 0.67003472 | D27: 2041 | E27: 1207 | F27: M1 | G27: 1046 | H27: Tanger/Casa | I27: 6.13 | J27: GSMR_02/03 | L27: Echec de connexion supervision radio ayant causé un Arret de Train | N27: Bord | P27: à fournir | Q27: à fournir | R27: à fournir | S27: en attente décision de remplacement CAB Radio | T27: H.O non finalisé entre 202 et 201 | U27: dl Rxqual=2 | V27: dl rx level= -49 dbm | W27: NOK | X27: OK | Y27: retransmission des trames HDLC*5
A28: 221 | B28: 45439.677 | C28: 0.67731481 | D28: 2041 | E28: 1202 | F28: M1 | G28: 1043 | H28: Tanger/Casa | I28: 48.426 | J28: GSMR_08/09 | K28: 6 | L28: Echec de connexion supervision radio ayant causé un Arret de Train | N28: Bord | P28: à fournir | Q28: à fournir | R28: à fournir | S28: en attente décision de remplacement CAB Radio | T28: H.O Complet entre 208 et 209 | U28: dl Rxqual=0 | V28: dl rx level= -55 dbm | W28: OK | X28: OK | Y28: retransmission des trames HDLC*5
A29: 228 | B29: 45440.838 | C29: 0.838125 | D29: 1049 | E29: 1202 | F29: M2 | G29: 1023 | H29: Casa/Tanger | I29: 25.91 | J29: GSMR_05/06 | K29: 1 | L29: Echec de connexion supervision radio ayant causé un Arret de Train | N29: Bord | P29: à fournir | Q29: à fournir | R29: à fournir | S29: en attente décision de remplacement CAB Radio | T29: H.O non finalisé entre 207 et 305 | U29: dl Rxqual=7 | V29: dl rx level= -93 dbm | W29: OK | X29: OK | Y29: retransmission des trames HDLC*5
A30: 233 | B30: 45441.795 | C30: 0.79493056 | E30: 1209 | F30: M2 | G30: 1033 | H30: Casa/Tanger | I30: 7.321 | J30: GSMR_02/03 | K30: 11 | L30: Echec de connexion supervision radio ayant causé un Arret de Train | N30: Bord | P30: à fournir | Q30: à fournir | R30: à fournir | S30: en attente décision de remplacement CAB Radio | T30: H.O non finalisé entre 303 et 202 | U30: dl Rxqual=7 | V30: dl rx level= -54 dbm | W30: OK | X30: OK | Y30: retransmission des trames HDLC*5
A31: 235 | B31: 45442.937 | C31: 0.39341435 | D31: 2013 | E31: 1201 | F31: M1 | G31: 7198 | H31: Tanger/Casa | I31: 97.619 | J31: GSMR_17/18 | L31: Echec de connexion supervision radio ayant causé un Arret de Train | N31: Bord | P31: à fournir | Q31: à fournir | R31: à fournir | S31: en attente décision de remplacement CAB Radio | T31: H.O Complet entre 217 et 218 | U31: dl Rxqual=0 | V31: dl rx level= -48 dbm | W31: OK | X31: OK | Y31: retransmission des trames HDLC*5
B32: 45442.937 | C32: 0.54261574 | D32: 1021 | E32: 1204 | F32: M2 | G32: 1031 | H32: Casa/Tanger | I32: 17.59 | J32: GSMR_04/05 | K32: 3 | L32: Echec de connexion supervision radio ayant causé un Arret de Train | N32: Bord/GSMR | P32: à fournir | Q32: à fournir | R32: à fournir | S32: en attente décision de remplacement CAB Radio / Zone Sous surveillance | T32: H.O Complet entre 305 et 204 | U32: dl Rxqual=0 | V32: dl rx level= -52 dbm | W32: OK | X32: OK | Y32: retransmission des trames HDLC*5
A33: 239 | B33: 45442.937 | C33: 0.87877315 | D33: 2061 | E33: 1211 | F33: M1 | G33: 1028 | H33: Tanger/Casa | I33: 6.13 | J33: GSMR_02/03 | K33: 1 | L33: Echec de connexion supervision radio ayant causé un Arret de Train | N33: Bord | P33: à fournir | Q33: à fournir | R33: à fournir | S33: en attente décision de remplacement CAB Radio | T33: H.O non finalisé entre 302 et 201 | U33: dl Rxqual=4 | V33: dl rx level= -56 dbm | W33: OK | X33: OK | Y33: retransmission des trames HDLC*5
A34: 242 | B34: 45444 | C34: 0.55820602 | D34: 1025 | E34: 1208 | F34: M2 | G34: 1044 | H34: Casa/Tanger | I34: 133.7 | J34: GSMR_23/24 | K34: 5 | L34: Echec de connexion supervision radio ayant causé un Arret de Train | P34: à fournir | Q34: à fournir | R34: à fournir | T34: H.O Complet entre 99 et 233 | U34: dl Rxqual=7 | V34: dl rx level= -66 dbm | W34: OK | X34: OK | Y34: retransmission des trames HDLC*5
A35: 243 | B35: 45444 | C35: 0.71216435 | D35: 2045 | E35: 1201 | F35: M1 | G35: 7206 | H35: Tanger/Casa | I35: 6.13 | J35: GSMR_02/03 | L35: Echec de connexion supervision radio ayant causé un Arret de Train | P35: à fournir | Q35: à fournir | R35: à fournir | T35: H.O non finalisé entre 202 et 201 | U35: dl Rxqual=7 | V35: dl rx level= -55 dbm | W35: NOK | X35: OK | Y35: retransmission des trames HDLC*5
A36: 250 | B36: 45446 | C36: 0.79491898 | D36: 2053 | E36: 1201 | F36: M1 | G36: 1045 | H36: Tanger/Casa | I36: 6.13 | J36: GSMR_02/03 | K36: 1 | L36: Echec de connexion supervision radio ayant causé un Arret de Train | P36: à fournir | Q36: à fournir | R36: à fournir | T36: H.O non finalisé entre 202 et 303 | U36: dl Rxqual=4 | V36: dl rx level= -52 dbm | W36: OK | X36: OK | Y36: retransmission des trames HDLC*5
A37: 253 | B37: 45447 | C37: 0.9615162 | D37: 1061 | E37: 1207 | F37: M2 | G37: 1007 | H37: Casa/Tanger | I37: 7.321 | J37: GSMR_02/03 | K37: 1 | L37: Echec de connexion supervision radio ayant causé un Arret de Train | P37: à fournir | Q37: à fournir | R37: à fournir | T37: H.O non finalisé entre 303 et 202 | U37: dl Rxqual=7 | V37: dl rx level= -56 dbm | W37: OK | X37: OK | Y37: retransmission des trames HDLC*5
A38: 257 | B38: 45452 | C38: 0.66559028 | D38: 1034 | E38: 1211 | F38: M2 | G38: 3062 | H38: Casa/Tanger | I38: 26.739 | J38: GSMR_05/06 | L38: Echec de connexion supervision radio ayant causé un Arret de Train | M38: H.O Complet entre 307 et 306 Bonne qualité de signal ,Requête de déconnexion a été envoyé par le RBC | N38: BORD | P38: à fournir | Q38: à fournir | R38: ok | S38: Dans l'attente de la mise en place des tiroires monomode | T38: H.O Complet entre 307 et 306 | U38: dl Rxqual=0 | V38: dl rx level= -48 dbm | W38: OK | X38: OK | Y38: retransmission des trames HDLC*5
A39: 259 | B39: 45453 | C39: 0.83270833 | D39: 1049 | E39: 1209 | F39: M2 | G39: 1033 | H39: Casa/Tanger | I39: 31.351 | J39: GSMR_06/07 | L39: Echec de connexion supervision radio ayant causé un Arret de Train | M39: H.O Complet entre 307 et 306 Bonne qualité de signal ,Requête de déconnexion a été envoyé par le RBC | N39: BORD | P39: à fournir | Q39: à fournir | R39: ok | S39: Dans l'attente de la mise en place des tiroires monomode | T39: H.O Complet entre 307 et 306 | U39: dl Rxqual=0 | V39: dl rx level= -48 dbm | W39: OK | X39: OK | Y39: Pas de retransmission des trames HDLC
A40: 261 | B40: 45454 | C40: 07:22:20 | D40: 2005 | E40: 1201 | F40: M1 | G40: 7198 | H40: Tanger/Casa | I40: 78.155 | J40: GSMR_14/15 | L40: Echec de connexion supervision radio ayant causé un arrêt de train | M40: H.O finalisé entre 214 et 215 bonne qualité de signal, Requête de déconnexion a été envoyé à travers la BTS | N40: BORD | P40: à fournir | Q40: à fournir | R40: ok | S40: Dans l'attente de la mise en place des tiroires monomode | T40: H.O finalisé entre 214 et 215 | U40: dl Rxqual=0 | V40: dl rx level= -53 dbm | W40: OK | X40: OK | Y40: Pas de retransmission des trames HDLC
...

Sheet Synthèse Hebdo
G1: Date | H1: (Tous)
A2: 7 derniers jours? | B2: VRAI | G2: 7 derniers jours? | H2: VRAI | K2: 7 derniers jours? | L2: VRAI | N2: 7 derniers jours? | O2: VRAI
BS3: Date | BT3: (Tous)
A4: Nombre de Rame | G4: Sous-Système | H4: Nb dcnx | K4: Intervalle | L4: Nombre | N4: Nombre de Rame | O4: Sous système mis encause | AB4: 7 derniers jours? | AC4: VRAI | AR4: 7 derniers jours? | AS4: VRAI | BS4: 7 derniers jours? | BT4: VRAI
B5: M1 | C5: M2 | D5: Total | G5: BORD | H5: 6 | K5: GSMR_02/03 | L5: 6 | N5: Rame | O5: BORD | P5: Total général
